<?xml version="1.0" encoding="UTF-8"?>
<robot xmlns:xacro="http://www.ros.org/wiki/xacro" name="trottle_control_unit">
  <link name="base_link">
    <visual>
      <origin xyz="0 0 0" rpy="${pi/2} 0 0"/>
      <geometry>
        <mesh filename="package://throt_control_description/meshes/throttle_control.stl" scale="0.001 0.001 0.001"/>
      </geometry>
      <material name="acrylic">
        <color rgba="1 0.9 1 1"/>
      </material>
    </visual>
    <collision>
      <origin xyz="0 0 0" rpy="0 0 0"/>
      <geometry>
        <mesh filename="package://throt_control_description/meshes/throttle_control.stl" scale="0.001 0.001 0.001"/>
      </geometry>
    </collision>
  </link>

  <link name="nut_assem">
    <visual>
      <origin xyz="0 0 0" rpy="0 0 -${pi/2}"/>
      <geometry>
        <mesh filename="package://throt_control_description/meshes/nut_assem.stl" scale="0.001 0.001 0.001"/>
      </geometry>
      <material name="grey">
        <color rgba="0.4 0.4 0.4 1"/>
      </material>
    </visual>
    <collision>
      <origin xyz="0 0 0" rpy="0 0 0"/>
      <geometry>
        <mesh filename="package://throt_control_description/meshes/nut_assem.stl" scale="0.001 0.001 0.001"/>
      </geometry>
    </collision>
  </link>

  <joint name="base_link_nut_assem" type="prismatic">
    <origin xyz="0.14 -0.020 0.016" rpy="0 0 0"/>
    <parent link="base_link"/>
    <child link="nut_assem"/>
    <axis xyz="1 0 0"/>
    <limit lower="0.0" upper="-0.04" effort="10" velocity="0.01"/>
  </joint>
</robot>
